Workbook
Name All: [1]All!$B$35:$P$54
Name All: All!$B$35:$P$54
Name Ambulanta__Sve_na_jednom_mjestu__za_djecu_i_osobe_s_poteškoćama_u_razvoju: [1]Sheet2!$E$2:INDEX([1]Sheet2!$E:$E,COUNTA([1]Sheet2!$E:$E))
Name Ambulanta__Sve_na_jednom_mjestu__za_djecu_i_osobe_s_poteškoćama_u_razvoju: Sheet2!$E$2:INDEX(Sheet2!$E:$E,COUNTA(Sheet2!$E:$E))
Name dob: Sheet2!$D$2:$D$8
Name N: OFFSET([1]Sheet2!$E$2, 0, 0, COUNTA([1]Sheet2!$E:$E), 1)
Name N: OFFSET(Sheet2!$E$2, 0, 0, COUNTA(Sheet2!$E:$E), 1)
Name Novorodjence: Sheet2!$E$2:$E$32
Name Postupci: 'Administrativni postupci'!$B$2:$B$45
Name Slicer_Ministartvo_Organizacija: #N/A
Name Slicer_Tip_usluge_prava_benefita: #N/A
Name Slicer_Životna_dob: #N/A
Name Zivotna_dob: Sheet2!$D$1:$D$6

Sheet Filter
A1: {=_xlfn._xlws.FILTER('Administrativni postupci'!$B$2:$B$95,ISNUMBER(SEARCH("Novorođenče",'Administrativni postupci'!$D$2:$D$95)), "0")} -> 0 | B1: {=_xlfn._xlws.FILTER('Diskrecione usluge'!$A$2:$A$94,ISNUMBER(SEARCH("Novorođenče",'Diskrecione usluge'!$D$2:$D$94)), "0")} -> 0 | C1: {=_xlfn._xlws.FILTER('Neinstitucionalizirana prava'!$A$2:$A$97,ISNUMBER(SEARCH("Novorođenče",'Neinstitucionalizirana prava'!$C$2:$C$97)), "0")} -> 0 | D1: {=_xlfn._xlws.FILTER('Administrativni postupci'!$B$2:$B$95,ISNUMBER(SEARCH("Predškolska dob",'Administrativni postupci'!$D$2:$D$95)),"0")} -> Jednokratna novčana pomoć licima i domaćinstvima sa područja općine Novo Sarajevo | E1: {=_xlfn._xlws.FILTER('Diskrecione usluge'!$A$2:$A$94,ISNUMBER(SEARCH("Predškolska dob",'Diskrecione usluge'!$D$2:$D$94)),"0")} -> Ambulanta "Sve na jednom mjestu" za djecu i osobe s poteškoćama u razvoju | F1: {=_xlfn._xlws.FILTER('Neinstitucionalizirana prava'!$A$2:$A$97,ISNUMBER(SEARCH("Predškolska dob",'Neinstitucionalizirana prava'!$C$2:$C$97)),"0")} -> Pravo na penziju korsnika ili roditelja/staratelja | G1: {=_xlfn._xlws.FILTER('Administrativni postupci'!$B$2:$B$95,ISNUMBER(SEARCH("Školska dob",'Administrativni postupci'!$D$2:$D$95)),"0")} -> Jednokratna novčana pomoć licima i domaćinstvima sa područja općine Novo Sarajevo | H1: {=_xlfn._xlws.FILTER('Diskrecione usluge'!$A$2:$A$94,ISNUMBER(SEARCH("Školska dob",'Diskrecione usluge'!$D$2:$D$94)),"0")} -> Ambulanta "Sve na jednom mjestu" za djecu i osobe s poteškoćama u razvoju | I1: {=_xlfn._xlws.FILTER('Neinstitucionalizirana prava'!$A$2:$A$97,ISNUMBER(SEARCH("Školska dob",'Neinstitucionalizirana prava'!$C$2:$C$97)),"0")} -> Pravo na dnevni boravak u posebnim ustanovama ili smještaj u domovima tokom obrazovanja. Potpuno pokriće troškova dnevnog boravka od strane Centra | J1: {=_xlfn._xlws.FILTER('Administrativni postupci'!$B$2:$B$95,ISNUMBER(SEARCH("Radni vijek",'Administrativni postupci'!$D$2:$D$95)),"0")} -> Izdavanje međunarodnog znaka pristupačnosti | K1: {=_xlfn._xlws.FILTER('Diskrecione usluge'!$A$2:$A$94,ISNUMBER(SEARCH("Radni vijek",'Diskrecione usluge'!$D$2:$D$94)),"0")} -> Ambulanta "Sve na jednom mjestu" za djecu i osobe s poteškoćama u razvoju | L1: {=_xlfn._xlws.FILTER('Neinstitucionalizirana prava'!$A$2:$A$97,ISNUMBER(SEARCH("Radni vijek",'Neinstitucionalizirana prava'!$C$2:$C$97)),"0")} -> Pravo na kućnu njegu | M1: {=_xlfn._xlws.FILTER('Administrativni postupci'!$B$2:$B$95,ISNUMBER(SEARCH("Treća životna dob",'Administrativni postupci'!$D$2:$D$95)),"0")} -> Usluga dnevnog ili poludnevnog boravka u Centar za dnevni boravak – Gerontološki centar | N1: {=_xlfn._xlws.FILTER('Diskrecione usluge'!$A$2:$A$94,ISNUMBER(SEARCH("Treća životna dob",'Diskrecione usluge'!$D$2:$D$94)),"0")} -> Ambulanta "Sve na jednom mjestu" za djecu i osobe s poteškoćama u razvoju | O1: {=_xlfn._xlws.FILTER('Neinstitucionalizirana prava'!$A$2:$A$97,ISNUMBER(SEARCH("Treća životna dob",'Neinstitucionalizirana prava'!$C$2:$C$97)),"0")} -> Pravo na kućnu njegu
D2: Posebni programi za osobe oboljele od teških i rijetkih bolesti (npr. enteralna prehrana za djecu i odrasle, bezglutensko brašno za osobe oboljele od celijakije) | E2: Usluge centara za prevenciju i rehabilitaciju, defektologa, logopeda | F2: Pravo roditelja/staratelja njegovatelja na osiguranje | G2: Posebni programi za osobe oboljele od teških i rijetkih bolesti (npr. enteralna prehrana za djecu i odrasle, bezglutensko brašno za osobe oboljele od celijakije) | H2: Asistent u nastavi | I2: Pravo na penziju korsnika ili roditelja/staratelja | J2: Jednokratna novčana pomoć licima i domaćinstvima sa područja općine Novo Sarajevo | K2: Jednokratna novčana pomoć za invalidna lica | L2: Pravo na penziju korsnika ili roditelja/staratelja | M2: Izdavanje međunarodnog znaka pristupačnosti | N2: Jednokratna novčana pomoć za invalidna lica
D3: Medicinska rehabilitacija/banjsko liječenje kao produženo bolničko liječenje | E3: Jednokratna novčana pomoć za invalidna lica | F3: Pravo roditelja/staratelja njegovatelja na pokrivanje troškova sahrane/dženaze | G3: Medicinska rehabilitacija/banjsko liječenje kao produženo bolničko liječenje | H3: Usluge centara za prevenciju i rehabilitaciju, defektologa, logopeda | I3: Pravo na produženo obrazovanje | J3: Posebni programi za osobe oboljele od teških i rijetkih bolesti (npr. enteralna prehrana za djecu i odrasle, bezglutensko brašno za osobe oboljele od celijakije) | K3: Jednokratna novčana pomoć za teško bolesne osobe | L3: Pravo na skraćeno radno vrijeme, zaštita od prekovremenog rada i rada noću, kao i zaštita od promjene mjesta rada | M3: Jednokratna novčana pomoć licima i domaćinstvima sa područja općine Novo Sarajevo | N3: Jednokratna novčana pomoć za stanovnike starije od 80 godina
D4: Medicinska sredstva - ortopedska pomagala (npr. invalidska kolica, pelene, GPS narukvice za djecu, perike od prirodne kose za djecu, senzori, inzulinske pumpice) | E4: Jednokratna novčana pomoć za teško bolesne osobe | G4: Medicinska sredstva - ortopedska pomagala (npr. invalidska kolica, pelene, GPS narukvice za djecu, perike od prirodne kose za djecu, senzori, inzulinske pumpice) | H4: Jednokratna novčana pomoć za invalidna lica | I4: Pravo na srednje obrazovanje u redovnim ili specijalnim školama | J4: Medicinska rehabilitacija/banjsko liječenje kao produženo bolničko liječenje | K4: Oslobađanje od plaćanja RTV takse za osobe koje su izgubile sluh i vid | L4: Pravo na zapošljavanje: povlaštena prava pri zapošljavanju u javnom sektoru | M4: Usluga kućne njege i pomoći u kući od strane osoblja Gerontološkog centra | N4: Jednokratna novčana pomoć za teško bolesne osobe
D5: Novčana pomoć i upućivanje na dijagnostiku i liječenje djece | E5: Oslobađanje od plaćanja RTV takse za osobe koje su izgubile sluh i vid | G5: Novčana pomoć i upućivanje na dijagnostiku i liječenje djece | H5: Jednokratna novčana pomoć za teško bolesne osobe | I5: Pravo roditelja/staratelja njegovatelja na osiguranje | J5: Medicinska sredstva - ortopedska pomagala (npr. invalidska kolica, pelene, GPS narukvice za djecu, perike od prirodne kose za djecu, senzori, inzulinske pumpice) | K5: Oslobađanje plaćanja uvoznih dadžbina, carine i PDV-a prilikom uvoza automobila | L5: Pravo roditelja/staratelja njegovatelja na osiguranje | M5: Kupovina lijekova penzionerima i licima preko 60 godina starosti bez primanja | N5: Oslobađanje od plaćanja RTV takse za osobe koje su izgubile sluh i vid
D6: Novčana pomoć za nabavku GPS narukvica | E6: Oslobađanje plaćanja uvoznih dadžbina, carine i PDV-a prilikom uvoza automobila | G6: Novčana pomoć za nabavku GPS narukvica | H6: Oslobađanje od plaćanja RTV takse za osobe koje su izgubile sluh i vid | I6: Pravo roditelja/staratelja njegovatelja na pokrivanje troškova sahrane/dženaze | J6: Medicinsko - sanitetski materijal za RVI sa područja Kantona Sarajevo | K6: Osnovni paket fiksne telefonije - socijalni | L6: Pravo roditelja/staratelja njegovatelja na pokrivanje troškova sahrane/dženaze | M6: Posebni programi za osobe oboljele od teških i rijetkih bolesti (npr. enteralna prehrana za djecu i odrasle, bezglutensko brašno za osobe oboljele od celijakije) | N6: Oslobađanje plaćanja uvoznih dadžbina, carine i PDV-a prilikom uvoza automobila
D7: Ocjenjivanje sposobnosti, razvrstavanje djece i omladine ometene u psiho-fizičkom razvoju | E7: Osnovni paket fiksne telefonije - socijalni | G7: Ocjenjivanje sposobnosti, razvrstavanje djece i omladine ometene u psiho-fizičkom razvoju | H7: Oslobađanje plaćanja uvoznih dadžbina, carine i PDV-a prilikom uvoza automobila | J7: Pravo na ličnu invalidninu, dodatak za njegu i pomoć drugog lica i ortopedski dodatak | K7: Umanjenje poreza na dohodak za zaposlene | M7: Medicinska rehabilitacija/banjsko liječenje kao produženo bolničko liječenje | N7: Osnovni paket fiksne telefonije - socijalni
D8: Pravo na ličnu invalidninu, dodatak za njegu i pomoć drugog lica i ortopedski dodatak | E8: Umanjenje poreza na dohodak za zaposlene | G8: Osposobljavanje za samostalan život i rad kroz srednje obrazovanje | H8: Osnovni paket fiksne telefonije - socijalni | J8: Pravo na novčanu naknadu za vrijeme čekanja na zaposlenje | K8: Posebna ishrana - enteralna prehrana za djecu i odrasle; bezglutensko brašno za oboljele od celijaklije | M8: Medicinska sredstva - ortopedska pomagala (npr. invalidska kolica, pelene, GPS narukvice za djecu, perike od prirodne kose za djecu, senzori, inzulinske pumpice) | N8: Posebna ishrana - enteralna prehrana za djecu i odrasle; bezglutensko brašno za oboljele od celijaklije
D9: Pravo na stalnu novčanu pomoć | E9: Posebna ishrana - enteralna prehrana za djecu i odrasle; bezglutensko brašno za oboljele od celijaklije | G9: Pravo na ličnu invalidninu, dodatak za njegu i pomoć drugog lica i ortopedski dodatak | H9: Umanjenje poreza na dohodak za zaposlene | J9: Pravo na poslovnu rehabilitaciju | K9: Povlastice u željezničkom saobraćaju | M9: Medicinsko - sanitetski materijal za RVI sa područja Kantona Sarajevo | N9: Povlastice u željezničkom saobraćaju
D10: Pravo na zdravstvenu zaštitu | E10: Povlastice u željezničkom saobraćaju | G10: Pravo na stalnu novčanu pomoć | H10: Posebna ishrana - enteralna prehrana za djecu i odrasle; bezglutensko brašno za oboljele od celijaklije | J10: Pravo na stalnu novčanu pomoć | K10: Prednost u primanju usluga u zdravstvenom i drugim institucijama | M10: Pravo na ličnu invalidninu, dodatak za njegu i pomoć drugog lica i ortopedski dodatak | N10: Prednost u primanju usluga u zdravstvenom i drugim institucijama
D11: Priznavanje statusa roditelja njegovatelja | E11: Pružanje oralno-hirurških i stomatoloških usluga za djecu sa poteškoćama u razvoju | G11: Pravo na zdravstvenu zaštitu | H11: Povlastice u željezničkom saobraćaju | J11: Pravo na zdravstvenu zaštitu | K11: Usluge savjetodavno-terapeutskog rada (individualno, psihološko, grupno, porodično savjetovanje i tretman) | M11: Pravo na novčanu naknadu za pomoć i njegu od strane druge osobe (lica iznad 65 godina života) | N11: Usluge savjetodavno-terapeutskog rada (individualno, psihološko, grupno, porodično savjetovanje i tretman)
D12: Refundacija troškova lijekova i liječenja | E12: Subvencija za djecu istih roditelja - oslobađanje plaćanja vrtića za braću i sestre djeteta sa poteškoćama u razvoju | G12: Priznavanje statusa roditelja njegovatelja | H12: Pravo na druge primjerene oblike pomoći djeci u predškolskim ustanovama, redovnim osnovnim i srednjim školama i ustanovama osnovnoškolskog i srednjoškolskog odgoja obrazovanja i rehabilitacije za učenike sa teškoćama (ustanove): a. Program edukacijsko rehabilitacijskih tretmana b. Program produženog stručnog postupka c. Rehabilitacijski programi | J12: Priznavanje statusa roditelja njegovatelja | K12: Usluge psihosocijalne podrške grupama korisnika sa istim ili sličnim problemima ( grupno savjetovanje i tretman) | M12: Pravo na stalnu novčanu pomoć | N12: Usluge psihosocijalne podrške grupama korisnika sa istim ili sličnim problemima ( grupno savjetovanje i tretman)
D13: Smještaj u hospis | E13: Uvećani dječiji doplatak | G13: Refundacija troškova lijekova i liječenja | H13: Pravo na individualni prilagođeni program (IPP) – IPP1 IPP2 IPP3 | J13: Refundacija troškova lijekova i liječenja | K13: Pravo na dodjelu jednokratne novčane pomoći putem sufinansiranja troškova nabavke ortopedskih pomagala i prilagođavanja stambenih objekata i motornih vozila individualnim licima | M13: Pravo na zdravstvenu zaštitu | N13: Pravo na dodjelu jednokratne novčane pomoći putem sufinansiranja troškova nabavke ortopedskih pomagala i prilagođavanja stambenih objekata i motornih vozila individualnim licima
D14: Smještaj u ustanovu, njega, rehabilitacija i socijalna zaštita – Dom za djecu bez roditeljskog staranja | E14: Prednost u primanju usluga u zdravstvenom i drugim institucijama | G14: Smještaj u hospis | H14: Pružanje oralno-hirurških i stomatoloških usluga za djecu sa poteškoćama u razvoju | J14: Smještaj u hospis | M14: Refundacija troškova lijekova i liječenja
D15: Sufinansiranje troškova prijevoza djece sa poteškoćama u kretanju | E15: Pravo na dodjelu jednokratne novčane pomoći putem sufinansiranja troškova nabavke ortopedskih pomagala i prilagođavanja stambenih objekata i motornih vozila individualnim licima | G15: Smještaj u ustanovu, njega, rehabilitacija i socijalna zaštita – Dom za djecu bez roditeljskog staranja | H15: Subvencija za djecu istih roditelja - oslobađanje plaćanja vrtića za braću i sestre djeteta sa poteškoćama u razvoju | J15: Pravo na invalidsku penziju/mirovinu | M15: Smještaj u Gerontološki centar – Privatni ugovori potpisani sa fizičkim licima
G16: Sufinansiranje troškova prijevoza djece sa poteškoćama u kretanju | H16: Uvećani dječiji doplatak | J16: Pravo na invalidsku penziju/mirovinu za policijske službenike | M16: Smještaj u hospis
H17: Prednost u primanju usluga u zdravstvenom i drugim institucijama | J17: Naknada za fizičku onesposobljenost kao rezultat rada | M17: Smještaj u ustanovu, njega, rehabilitacija i socijalna zaštita – Gerontološki centar
H18: Pravo na dodjelu jednokratne novčane pomoći putem sufinansiranja troškova nabavke ortopedskih pomagala i prilagođavanja stambenih objekata i motornih vozila individualnim licima | M18: Stalna novčana pomoć za kupovinu hljeba i mlijeka lica starija od 60 godina bez primanja
M19: Stalna novčana pomoć za kupovinu hljeba i mlijeka penzioneri sa minimalnom penzijom
M20: Zdravstvena zaštita starijih od 65 godina
M21: Pravo na invalidsku penziju/mirovinu
M22: Pravo na invalidsku penziju/mirovinu za policijske službenike
M23: Naknada za fizičku onesposobljenost kao rezultat rada

Sheet Pivot
A3: Životna dob | B3: Naziv
A4: Novorođenče | B4: Ambulanta "Sve na jednom mjestu" za djecu i osobe s poteškoćama u razvoju
B5: Dodatak za njegu i pomoć od strane drugog lica, Civilne žrtve rata
B6: Jednokratna novčana pomoć licima i domaćinstvima sa područja općine Novo Sarajevo
B7: Jednokratna novčana pomoć za invalidna lica
B8: Jednokratna novčana pomoć za teško bolesne osobe i umjetnu oplodnju
B9: Kupovina lijekova po posebnim protokolima
B10: Medicinska rehabilitacija/banjsko liječenje kao produženo bolničko liječenje
B11: Medicinska sredstva - ortopedska pomagala
B12: Ocjenjivanje sposobnosti, razvrstavanje djece i omladine ometene u psiho-fizičkom razvoju
B13: Osnovna dijagnostika
B14: Osnovni paket fiksne telefonije - socijalni
B15: Porez na dohodak, umanjenje poreza na zaposlene osobe sa invaliditetom
B16: Posebna ishrana
... B32: Uvećani dječiji doplatak
A33: Novorođenče Total
A34: Predškolska dob | B34: Ambulanta "Sve na jednom mjestu" za djecu i osobe s poteškoćama u razvoju
B35: Dodatak za njegu i pomoć od strane drugog lica, Civilne žrtve rata
B36: Jednokratna novčana pomoć licima i domaćinstvima sa područja općine Novo Sarajevo
B37: Jednokratna novčana pomoć za invalidna lica
B38: Jednokratna novčana pomoć za teško bolesne osobe i umjetnu oplodnju
B39: Kupovina lijekova po posebnim protokolima
B40: Medicinska rehabilitacija/banjsko liječenje kao produženo bolničko liječenje
B41: Medicinska sredstva - ortopedska pomagala
B42: Novčana pomoć i upućivanje na dijagnostiku i liječenje djece
B43: Novčana pomoć za nabavku GPS narukvica
B44: Ocjenjivanje sposobnosti, razvrstavanje djece i omladine ometene u psiho-fizičkom razvoju
B45: Osnovna dijagnostika
B46: Osnovni paket fiksne telefonije - socijalni
... B66: Uvećani dječiji doplatak
A67: Predškolska dob Total
A68: Radni vijek | B68: Ambulanta "Sve na jednom mjestu" za djecu i osobe s poteškoćama u razvoju
B69: Izdavanje međunarodnog znaka pristupačnosti
B70: Jednokratna novčana pomoć licima i domaćinstvima sa područja općine Novo Sarajevo
B71: Jednokratna novčana pomoć za invalidna lica
B72: Jednokratna novčana pomoć za teško bolesne osobe i umjetnu oplodnju
B73: Kupovina lijekova po posebnim protokolima
B74: Medicinska rehabilitacija/banjsko liječenje kao produženo bolničko liječenje
B75: Medicinska sredstva - ortopedska pomagala
B76: Medicinsko - sanitetski materijal za RVI sa područja Kantona Sarajevo
...

Sheet All (2)
A1: # | B1: Naziv | C1: Opis | D1: Životna dob | E1: Tip usluge/prava/benefita | F1: Ministartvo/Organizacija | G1: Adresa | H1: Web stranica | I1: Telefon | J1: Email | K1: Pravni osnov | L1: Proces aplikacije | M1: Lista neophodnih dokumenata | N1: Link za informacije o prijavi | O1: Dodatne napomene | P1: Pravo
A2: 22 | B2: Refundacija troškova lijekova i liječenja | C2: Pravo na refundiranje troškova lijekova, medicinskih sredstava i liječenja koji nisu obuhvaćeni obaveznim zdravstvenim osiguranjem (odobravanje sredstava do 20.000KM) | D2: Novorođenče | E2: Zdravstvena zaštita | F2: Zavod zdravstvenog osiguranja Kantona Sarajevo | G2: Ložionička 2, 71000 Sarajevo, Bosna i Hercegovina | H2: https://www.kzzosa.ba/ | I2: 38733725207 | J2: info@kzzosa.ba | K2: Pravilnik o načinu ostvarivanja prava iz obaveznog zdravstvenog osiguranja ("Sl.novine FBiH" br 31/02 i 20/19) i odluke ZZOKS | L2: Zahtjev za refundaciju troškova lijeka, medicinskog sredstva ili liječenja koji nisu obuhvaćenim obaveznim zdravstvenim osiguranjem, a preporučeni su pacijentu, podnosi se ZZO KS (odlučuje posebna komisija). Uz zahtjev se dostavlja medicinska dokumentacija kojom je preporučeno lijek, liječenje ili medicinsko sredstvo, potvrda o prebivalištu i originalni račun o plaćenom lijeku, liječenju ili medicinskom sredstvu. | P2: Administrativni postupci
A3: 46 | B3: Pravo na pelene | D3: Novorođenče | E3: Zdravstvena zaštita | F3: Zavod zdravstvenog osiguranja KS | P3: Diskrecione usluge
A4: 2 | B4: Dodatak za njegu i pomoć od strane drugog lica, Civilne žrtve rata | C4: Pravo na dodatak za pomoć i njegu od strane druge osobe invalidima od I do IV grupe koji su nesposobni za vršenje osnovnih životnih potreba bez pomoći drugog lica. | D4: Novorođenče | E4: Zaštita civilnih žrtava rata | F4: Općina, nadležna općinska služba Ministarstvo za rad, socijalnu politiku, raseljena lica i izbjeglice Kantona Sarajevo | G4: Primjer Općine Centar | H4: https://eregistar.centar.ba/registar/12-21-pravo-na-dodatak-za-njegu-i-pomoc-od-strane-drugog-lica-czr/ | I4: 0038733562450 | J4: zlatan.kulovic@centar.ba | K4: Zakon o osnovama socijalne zaštite, zaštite civilnih žrtava rata i zaštite porodice sa djecom („Službene novine Federacije Bosne i Hercegovine“, br. 36/99, 54/04, 39/06, 14/09, 45/16 i 40/18); član 60. Instrukcija o iznosima novčanih davanja po Zakonu o socijalnoj zaštiti, zaštiti civilnih žrtava rata i zaštiti porodice sa djecom – Instrukciju svake kalendarske godine donosi ministar za rad, socijalnu politiku, raseljena lica i izbjeglice Kantona Sarajevo. | L4: Državljanstvo Bosne i Hercegovine;Potreba za tuđom njegom i pomoći civilne žrtve rata utvrđuje se na osnovu nalaza i mišljenja nadležne ljekarske komisije određene propisom ministra Federalnog ministarstva rada i socijalne politike. Vodi se upravni postupak u kojem se utvrđuje ispunjavanje uslova za ostvarivanje prava na dodatak za njegu i pomoć od strane drugog lica. Podnosilac zahtjeva ima pravo podnijeti žalbu na rješenje prvostepenog organa kojim nije ostvario pravo na dodatak za njegu i pomoć od strane drugog lica Ministarstvu za rad, socijalnu politiku, raseljena lica i izbjeglice Kantona Sarajevo, kao i pokrenuti upravni spor pred Kantonalnim sudom u Sarajevu. da ima priznat status civilne žrtve rata i pravo na ličnu invalidninu i da je nalazom i mišljenjem od strane ljekarske komisije utvrđena potreba za ortopedskim dodatkom. • | M4: Zahtjev za ostvarivanje prava na dodatak za njegu i pomoć od strane drugog lica podnosi se općini, nadležnoj općinskoj službi općine u kojoj podnosilac zahtjeva ima prebivalište. • • rješenje o priznavanju statusa civilne žrtve rata i prava na ličnu invalidninu; • ovjerena kopija lične karte; • CIPS prijava o mjestu prebivališta i • medicinska dokumentacija. Uvjerenje o nekažnjavanju, Ovjerena izjava u skladu sa čl.7, stav 1. i 2., čl.74, čl.75, čl.76a i čl.77 Zakona o osnovama socijalne zaštite, zaštite civilnih žrtava rata i zaštite porodice sa djecom („Službene novine FBiH“ broj 36/99,54/04,39/06,14/09,45/16 i 40/18), Tekući račun podnosioca zahtjeva | P4: Administrativni postupci
A5: 13 | B5: Ocjenjivanje sposobnosti, razvrstavanje djece i omladine ometene u psiho-fizičkom razvoju | C5: Utvrđivanja preostale sposobnosti i razvrstavanja djece i omladine, vodi se do navršene 18. godine života djeteta. | D5: Novorođenče | E5: Socijalna zaštita | F5: Kantonalni centar za socijalni rad | G5: Gatačka 80, Sarajevo | H5: https://kcsr.ba/ | I5: 38733723640 | J5: info@kcsr.ba | K5: Pravilnik o utvrđivanju preostale sposobnosti i razvrstavanju djece i omladine ometene u psiho-fizičkom razvoju KS | M5: https://kcsr.ba/file/kcsr21/274 | N5: https://kcsr.ba/file/kcsr21/274 | P5: Administrativni postupci
A6: 25 | B6: Smještaj u ustanovu, njega, rehabilitacija i socijalna zaštita – Dom za djecu bez roditeljskog staranja | C6: Cjelokupno zbrinjavanje, odgoj, školovanje, zdravstvena zaštita djece bez roditelja i djece čiji je razvoj ometen porodičnim prilikama. | D6: Novorođenče | E6: Socijalna zaštita | F6: Kantonalna javna ustanova Dom za djecu bez roditeljskog staranja Javna ustanova “Kantonalni centar za socijalni rad” – službe socijalne zaštite Ministarstvo za rad, socijalnu politiku, raseljena lica i izbjeglice Kantona Sarajevo | G6: Bjelave 52, 71000 Sarajevo, Bosna i Hercegovina | H6: https://dombjelave.ba/bs | I6: 38733209044 | J6: dombjelave@hotmail.com | K6: Član 85 Dom za socijalno i zdravstveno zbrinjavanje osoba sa invaliditetom i drugih osoba obavlja poslove socijalno-zdravstvenog zbrinjavanja odraslih tjelesno i mentalno invalidnih osoba, osoba sa trajnim smetnjama u fizičkom ili psihičkom razvoju, duševno oboljelih i hronično bolesnih osoba, osoba sa specifičnim oboljenjima, ako ne postoje osnovni uvjeti za smještaj u vlastitoj ili drugoj porodici ili drugoj ustanovi, a nije im neophodno bolničko liječenje ili je bolničko liječenje završeno. • Zakon o socijalnoj zaštiti, zaštiti civilnih žrtava rata i zaštiti porodice sa djecom („Službene novine Kantona Sarajevo“ br. 38/14 – Prečišćeni tekst, 38/16, 44/17 i 28/18); član 94. | M6: zahtjev za smještaj; rješenje o smještaju; socijalna anamneza; izvod iz matične knjige rođenih; zdravstvena knjižica; medicinska dokumentacija (ukoliko dijete ima zdravstvene poteškoće) i rješenje o starateljstvu (ukoliko je dijete pod starateljstvom nadležne službe). | P6: Administrativni postupci
A7: 4 | B7: Jednokratna novčana pomoć licima i domaćinstvima sa područja općine Novo Sarajevo | C7: Jednokratna novčana pomoć licima i domaćinstvima sa područja općine Novo Sarajevo samo za osobe za prebivalištem u Općini Novo Sarajevo | D7: Novorođenče | E7: Socijalna zaštita | F7: Općina Novo Sarajevo | G7: Zmaja od Bosne 55, 71000 Sarajevo, Bosna i Hercegovina | H7: https://novosarajevo.ba/ | I7: 38733492125 | J7: socijalna.pitanja@novosarajevo.ba | K7: Odluka o uslovima, načinu, kriterijima i iznosu sredstava za dodjelu jednokratne novčane pomoći licima i domaćinstvima sa područja općine Novo Sarajevo ("Službene novine Kantona Sarajevo", broj: 19/21 i 19/22) | L7: Zahtjev se predaje Službi za socijalna pitanja, zdravstvo, izbjeglice i raseljena lica na propisanom obrascu, na kojem je navedena dokumentacija koju je potrebno priložiti. | M7: izjava - saglasnost za obradu podataka potvrda prijave mjesta prebivališta-boravišta (CIPS) za sve članove domaćinstva potvrda mjesne zajednice ili ovjerena kućna lista o broju članova domaćinstva potvrda banke o otvorenom žiro-računu preporuke stručnog lica medicinske struke original računi i dokaz o participaciji od Zavoda zdravstvenog osiguranja KS pravosnažno Rješenje ili uvjerenje JU "Centar za socijalni rad" dokaz o primanjima za sve članove domaćinstva ili potvrda o redovnom školovanju uvjerenje iz JU "Centar za socijalni rad" da li je njihov korisnik po bilo kom osnovu, za sve članove domaćinstva uvjerenje Porezne uprave, za sve članove domaćinstva | N7: https://novosarajevo.ba/userfiles/doc/files/Odluka_o_uslovima.pdf | O7: Zahtjevi se podnose tokom čitave godine, ali se pravo ostvaruje jednom u toku kalendarske godine | P7: Administrativni postupci
A8: 7 | B8: Kupovina lijekova po posebnim protokolima | C8: Pravo na liječenje rijetkih i teških oboljenja po posebnim protokolima (reumatoidini artritis, juvenilni idiopatski artritis, enteralna prehrana, bezglutensko brašno za oboljele od celijaklije) | D8: Novorođenče | E8: Zdravstvena zaštita | F8: Zavod zdravstvenog osiguranja Kantona Sarajevo/zdravstvene ustanove | G8: Ložionička 2, 71000 Sarajevo, Bosna i Hercegovina | H8: https://www.kzzosa.ba/ | I8: 38733725207 | J8: info@kzzosa.ba | K8: Posebni protokoli (zaključuju se na godišnjem nivou, dostupni na stranici Zavoda, rubrika Javnost rada) | L8: Ovlašteni ljekari (posebno utvrđeni po svakom protokolu) predlažu, a u odnosu na raspoloživa sredstva, komisija odobrava. Zdravstvena ustanova u kojoj su propisivači direktno podnosi zahtjev za uključivanjem pacijenta, a nakon odobrenja, na osnovu propisanog recepta pacijent ostvaruje pravo na lijek/sredstvo u apotekama ili neposredno u zdravstvenim ustanovama (ukoliko se po prirodi protokola liječenja, lijek aplicira samo u bolničkim uslovima) | P8: Administrativni postupci
A9: 8 | B9: Medicinska rehabilitacija/banjsko liječenje kao produženo bolničko liječenje | C9: Pravo na medicinsku rehabilitaciju u ugovornim banjama | D9: Novorođenče | E9: Zdravstvena zaštita | F9: Zavod zdravstvenog osiguranja Kantona Sarajevo | G9: Ložionička 2, 71000 Sarajevo, Bosna i Hercegovina | H9: https://www.kzzosa.ba/ | I9: 38733725207 | J9: info@kzzosa.ba | K9: Odluka o utvrđivanju osnovnog paketa zdravstvenih prava ("Sl.novine FBiH" br. 21/09) | L9: Ovlašteni ljekar/propisivač (neurolog, kardiolog itd) izdaju preporuku za medicinsku rehabilitaciju, koja se ovjerava u ZZO KS i osiguranik upućuje na medicinsku rehabilitaciju do 21 dana | P9: Administrativni postupci
A10: 9 | B10: Medicinska sredstva - ortopedska pomagala | C10: Pravo na medicinska sredstva/ortopedska pomagala za osiguranike u Kantonu Sarajevo | D10: Novorođenče | E10: Zdravstvena zaštita | F10: Zavod zdravstvenog osiguranja Kantona Sarajevo | G10: Ložionička 2, 71000 Sarajevo, Bosna i Hercegovina | H10: https://www.kzzosa.ba/ | I10: 38733725207 | J10: info@kzzosa.ba | K10: Odluka o obimu, uslovima i načinu ostvarivanja prava osiguranih lica Kantona Sarajevo na medicinska sredstva ("Službene novine Kantona Sarajevo", broj: 22/20, 30/21, 42/22 i 48/22) | L10: Ovlašteni ljekar/propisivač )ljekar porodične medicine, neurolog, dijabetolog itd.) popunjavaju obrazac o pravu na medicinsko sredstvo koji se ovjerava u ZZO KS i nakon toga osiguranik preuzima propisano medicinsko sredstvo u apotekama i/ili specijaliziranim trgovinama za promet medicinskim sredstvima | P10: Administrativni postupci
A11: 15 | B11: Pravo na ličnu invalidninu, dodatak za njegu i pomoć drugog lica i ortopedski dodatak | C11: Licima sa invaliditetom i grupe sa 100% tjelesnog oštećenja i licima sa invaliditetom II grupe sa 90% tjelesnog oštećenja, omogućiti ostvarivanje prava na ličnu invalidninu, dodatak za njegu i pomoć od strane drugog lica i ortopedski dodatak. | D11: Novorođenče | E11: Socijalna zaštita | F11: Kantonalni centar za socijalni rad | G11: Gatačka 80, Sarajevo | H11: https://kcsr.ba/ | I11: 38733723635 | J11: mirsada@kcsr.ba | K11: Zakon o osnovama socijalne zaštite zaštite civilnih žrtava rata i zaštite porodice sa djecom Federacije BiH Zakon o socijalnoj zaštiti, zaštiti civilnih žrtava rata i zaštiti porodice sa djecom Kantona Sarajevo | L11: (uvjerenje se pribavlja u općini prebivališta /boravišta podnosioca zahtjeva) (uvjerenje se pribavlja u općini prebivališta podnosioca zahtjeva) | M11: https://kcsr.ba/file/kcsr13/268 | N11: https://kcsr.ba/file/kcsr13/268 | P11: Administrativni postupci
A12: 19 | B12: Pravo na stalnu novčanu pomoć | C12: Ostvarivanje prava na materijalnu pomoć licima nesposobnim za rad, bez sredstava za život i srodnika koji su po Zakonu obavezni na izdržavanje. | D12: Novorođenče | E12: Socijalna zaštita | F12: Kantonalni centar za socijalni rad | G12: Gatačka 80, Sarajevo | H12: https://kcsr.ba/ | I12: 38733723635 | J12: mirsada@kcsr.ba | K12: Zakon o osnovama socijalne zaštite zaštite civilnih žrtava rata i zaštite porodice sa djecom Federacije BiH Zakon o socijalnoj zaštiti, zaštiti civilnih žrtava rata i zaštiti porodice sa djecom Kantona Sarajevo | L12: (matični ured prema mjestu rodjenja maloljetne osobe) (dokaz o primanjima – potvrda o visini ličnog dohotka, potvrda službe za zapošljavanje, potvrda PIO, potvrda škole/fakulteta) (nadležna je općina prebivališta članova domaćinstva) (dokaz o kvadraturi stambenog prostora -utvrdjuje se od strane stručnih radnika -na terenu – općine koja vodi postupak po osnovu zahtjeva) (nadležna je služba općine za obavljanje poslova iz oblasti zaštite civilnih žrtava rata i zaštite porodice sa djecom) (matični ured prema mjestu rodjenja maloljetne osobe) (nadležna je općina prebivališta članova domaćinstva) (Prema prebivalištu podnosioca zahtjeva) | M12: https://kcsr.ba/file/kcsr4/262 | N12: https://kcsr.ba/file/kcsr4/262 | P12: Administrativni postupci
A13: 20 | B13: Pravo na zdravstvenu zaštitu | C13: Ostvarivanje prava od strane lica-korisnika stalne novčane pomoći i lica sa invaliditetom pravo na zdravstvenu zaštitu ( pod uslovom da ga ne mogu ostvariti po drugom osnovu). | D13: Novorođenče | E13: Socijalna zaštita | F13: Kantonalni centar za socijalni rad | G13: Gatačka 80, Sarajevo | H13: https://kcsr.ba/ | I13: 38733723635 | J13: mirsada@kcsr.ba | K13: Zakon o osnovama socijalne zaštite zaštite civilnih žrtava rata i zaštite porodice sa djecom Federacije BiH Zakon o socijalnoj zaštiti, zaštiti civilnih žrtava rata i zaštiti porodice sa djecom Kantona Sarajevo | L13: (prema mjestu prebivališta podnosioca zahtjeva) | M13: https://kcsr.ba/file/kcsr7/264 | N13: https://kcsr.ba/file/kcsr7/264 | P13: Administrativni postupci
A14: 21 | B14: Priznavanje statusa roditelja njegovatelja | C14: Priznavanje statusa roditelja njegovatelja | D14: Novorođenče | E14: Socijalna zaštita | F14: Kantonalni centar za socijalni rad | G14: Gatačka 80, Sarajevo | H14: https://kcsr.ba/ | I14: 38733723635 | J14: mirsada@kcsr.ba | K14: Zakon o roditeljima njegovateljima u Federaciji BiH | L14: Da bi neko ostvario status roditelja njegovatelja te po osnovu statusa pravo na materijalnu podršku u vidu mjesečne naknade i pripadajućih doprinosa, potrebno je da podnese zahtjev (obrazac Zahtjeva se nalazi na Web stranici JU „Kantonalni Centar za socijalni rad u poglavlju Obrazci pod rednim brojem KCSR 23... ) Službi socijalne zaštite općine na čijem području ima posljednje prebivalište/ boravište. Podnosioci su dužni uz zahtjev priložiti dokaze navedene u Obrazcu zahtjeva. Pored toga, osobe koje ostvare pravo na status roditelja njegovatelja i po osnovu statusa pravo na materijalnu podršku, a koje imaju status rezidenta Federacije BiH i po osnovu statusa žele ostvariti pravo na osnovni lični odbitak i odbitke po osnovu izdržavanja članova uže porodice i po osnovu svog invaliditeta i invaliditeta članova porodice koje izdržavaju, moraju kod Porezne uprave Federacije pribaviti svoju poreznu karticu. | M14: https://kcsr.ba/file/kcsr-23/349 | N14: http://obrasci.pufbih.ba/images/stories/dohodak_docs/NoviObrazacPK1001hrv.pdf | P14: Administrativni postupci
A15: 33 | B15: Usluge centara za prevenciju | C15: Logopedi, defektolozi | D15: Novorođenče | E15: Zdravstvena zaštita | K15: Zakon o osnovama socijalne zaštite, zaštite civilnih žrtava rata i zaštite porodice s djecom, Član 88: Zaštita porodice sa djecom ima za cilj: da se osiguraju svoj djeci približno jednaki uvjeti za zdrav i pravilan tjelesni, intelektualni i emocionalni razvoj u porodici, pomoć u ostvarivanju njene reproduktivne uloge, njezi, podizanju, odgoju i zaštiti djece i poboljšanju kvaliteta života porodice, razvijanje humanih odnosa u skladu sa načelima građanskog morala i solidarnosti. Djetetu bez oba ili jednog roditelja, porodici koja ima dijete ometeno u fizičkom ili psihičkom razvoju i porodici u kojoj su oba ili jedan roditelj invalidi, osiguravaju se povoljniji uvjeti u sticanju i ostvarivanju prava i veći iznosi materijalnih i drugih davanja utvrđenih ovim zakonom i propisom kantona. | P15: Diskrecione usluge
A16: 49 | B16: Ugradnja inzulinske pumpice | C16: Osigurana lica - djeca do 18 godina, inzuloovisnici, na prijedlog tima za inzulinske pumpe pedijatrijske klinike, a uz odobrenje komisije Zavoda, mogu ostvariti pravo na inzulinsku pumpu. Uz inzulinsku pumpu obezbješuje se potrošni materijal: | D16: Novorođenče | E16: Zdravstvena zaštita | F16: Zavod zdravstvenog osiguranja KS | K16: Uredba o obimu, uvjetima i načiu ostvarivanja prava osiguranih lica na korištenje ortopedskih i drugih pomagala, endoproteza, stomatološko protetske pomoći i stomatološko - protetskih nadomjestaka https://www.kzzosa.ba/wp-content/uploads/2023/08/Odluka_o_visini_ucesca_ZZO_KS_u_cijeni_medicinskih_sredstava-1.pdf | P16: Diskrecione usluge
A17: 50 | B17: Uvećani dječiji doplatak | C17: Ako je neki član porodice lice sa invaliditetom, djeca imaju pravo na uvećani dječiji dodatak. Zakonom nije predviđen imovinski cenzus. Obratiti se nadležnoj službi u općini stanovanja, popuniti zahtjev i priložiti tražene dokumente. | D17: Novorođenče | E17: Socijalna zaštita | F17: Općine | P17: Diskrecione usluge
A18: 53 | B18: Pravo na penziju | C18: Osoba sa teškoćama u razvoju (nesposobnost za samostalan život, nesposobnost za privređivanje) ima pravo na penziju roditelja. | D18: Novorođenče | E18: Socijalna zaštita | K18: Član 73 (Uslovi za porodičnu penziju djeteta) (1) Dijete ima pravo na porodičnu penziju do navršenih 15 godina života. (2) Poslije navršenih 15 godina života, dijete ima pravo na porodičnu penziju do završetka redovnog školovanja, ali najkasnije do navršenih 26 godina života. (3) Redovnim školovanjem, u smislu ovog zakona, ne smatra se školovanje u školi istog ili nižeg stepena obrazovanja od škole koju je dijete završilo. (4) Dijete kod koga nastupi nesposobnost za samostalan život i rad prije 15. godine života ima pravo na porodičnu penziju dok ta nesposobnost traje. (5) Dijete kod koga nesposobnost za privređivanje nastupi poslije 15. godine života, a prije smrti osiguranika odnosno korisnika penzije ima pravo na porodičnu penziju ako ga je osiguranik odnosno korisnik penzije izdržavao do svoje smrti. (6) Dijete kod koga u toku korištenja prava na porodičnu penziju nastupi nesposobnost za samostalan život i rad ili nesposobnost za privređivanje zadržava pravo na penziju dok ta nesposobnost traje. (7) Nesposobnost za samostalan život i rad postoji kada se lice zbog vrste i težine fizičkog ili mentalnog oštećenja ili vrste i težine psihičke bolesti ne može osposobiti za obavljanje najjednostavnijih poslova. | P18: Neinstitucionalizirana prava
A19: 31 | B19: Ambulanta "Sve na jednom mjestu" za djecu i osobe s poteškoćama u razvoju | C19: Dodatna ambulanta nije namijenjena za prehlade, upale grla i sl. Nego, ukoliko dijete ili osoba sa teškoćama u razvoju treba istovremeno preglede, odnosno nalaze, kao što su vađenje krvi, EKG, RTG pluća, pedijatrijski pregled ili mišljenje anesteziologa. | D19: Novorođenče | E19: Zdravstvena zaštita | F19: Opća bolnica "Prim.dr. Abdulah Nakaš" | G19: Kranjčevićeva 12, Sarajevo | I19: 38733285261 | L19: Naručivanje u ambulanti. | P19: Diskrecione usluge
A20: 34 | B20: Jednokratna novčana pomoć za invalidna lica | C20: Općina Ilidža: Općinski načelnik dodjeljuje jednokratnu novčanu pomoć osobama sa invaliditetom sa posebnim potrebama koje su u socijalnoj potrebi. | D20: Novorođenče | E20: Socijalna zaštita | F20: Općina Ilidža | G20: Butmirska cesta 12, prvi sprat | H20: https://www.opcinailidza.ba/services/sluzba-za-socijalna-pitanja-zdravstvo-izbjeglice-i-raseljena-lica | I20: 387733637384 | J20: sejda.topalovic@opcinailidza.ba | K20: Pomoć se dodjeljuje kontinuirano posljednjih 10 godina | L20: Dodjela se vrši na osnovu evidencija Službe, a upis u evidenciju može se izvršti i na način da se dostavi dokumentacija Službi za socijalna pitanja, zdravstvo, izbjeglice i raseljena lica Općine Ilidža na adresi Butmirska cesta 12, -prvi sprat | M20: CIPS-ova prijava mjesta boravka Rješenje koje je doneseno u skladu Pravilnikom o utvrđivanju preostale sposobnosti i razvrstavanju djece i omladine ometene u psiho-fizičkom razvoju ("Službene novine Kantona Sarajevo" br. 26/08 i 5/12), odnsono medicinskom dokumentacijom za djecu oboljelu od od karcinoma, šećerne bolesti, leukemije, TBC i celijakije | N20: ZAHTJEV ZA PRIZNAVANJE PRAVA NA JEDNOKRATNU NOVČANU POMOĆ I SUFINANSIRANJE MEDICINSKI POTPOMOGNUTE OPLODNJE.pdf (opcinailidza.ba) | P20: Diskrecione usluge
A21: 36 | B21: Jednokratna novčana pomoć za teško bolesne osobe i umjetnu oplodnju | C21: Novčana pomoć za teško oboljela lica sa područja općine Ilidža kojima je potrebno plaćanje troškova liječenja u zemlji i/ili inostranstvu. | D21: Novorođenče | E21: Zdravstvena zaštita | F21: Općina Ilidža | G21: Butmirska cesta 12, prvi sprat | H21: ZAHTJEV ZA PRIZNAVANJE PRAVA NA JEDNOKRATNU NOVČANU POMOĆ I SUFINANSIRANJE MEDICINSKI POTPOMOGNUTE OPLODNJE.pdf (opcinailidza.ba) | I21: 387733637384 | J21: sejda.topalovic@opcinailidza.ba | K21: Za rješavanje zahtjeva nadležna je Komisija koju čine ljekari različitih specijalnosti | L21: ZAHTJEV ZA PRIZNAVANJE PRAVA NA JEDNOKRATNU NOVČANU POMOĆ I SUFINANSIRANJE MEDICINSKI POTPOMOGNUTE OPLODNJE.pdf (opcinailidza.ba) | M21: ZAHTJEV ZA PRIZNAVANJE PRAVA NA JEDNOKRATNU NOVČANU POMOĆ I SUFINANSIRANJE MEDICINSKI POTPOMOGNUTE OPLODNJE.pdf (opcinailidza.ba) | N21: ZAHTJEV ZA PRIZNAVANJE PRAVA NA JEDNOKRATNU NOVČANU POMOĆ I SUFINANSIRANJE MEDICINSKI POTPOMOGNUTE OPLODNJE.pdf (opcinailidza.ba) | P21: Diskrecione usluge
A22: 39 | B22: Osnovna dijagnostika | C22: Osobe s invaliditetom imaju pravo na besplatnu osnovnu dijagnostiku na KCUS-u i Domovizma zdravlja KS. | D22: Novorođenče | E22: Zdravstvena zaštita | F22: Klinički centar Univerziteta u Sarajevu i Domovi zdravlja Kantona Sarajevo | P22: Diskrecione usluge
A23: 40 | B23: Osnovni paket fiksne telefonije - socijalni | C23: Pravo na Socijalni paket ostvaruju: porodice palog borca, ratni vojni invalidi sa 100% invalidnosti, slijepa lica i kategorije, lica oboljela od distrofije i srodnih bolesti, paraplegičari, oboljeli od dječje ili cerebralne paralize i multiple skleroze i korisnici stalne novčane pomoći, u smislu zakona o osnovama socijalne zaštite, zaštite civilnih žrtava rata i zaštite porodica sa djecom i odgovarajućih kantonalnih pozitivnih propisa u FBiH, kojima se uređuje ova oblast. | D23: Novorođenče | E23: Kultura i sport | F23: BH Telecom | G23: Zmaja od Bosne 88 | H23: https://mojwebshop.bhtelecom.ba/INTERSHOP/web/BOS/BHTelecomWebShop-BHTelecom-Site/bs_BA/-/BAM/ViewProduct-Start?SKU=100003 | I23: 38733653093 | P23: Diskrecione usluge
A24: 41 | B24: Porez na dohodak, umanjenje poreza na zaposlene osobe sa invaliditetom | C24: Zaposlene osobe s invaliditetom imaju pravo na osnovni lični odbitak i umanjenje porezne osnovice po osnovu izdražavanja članova uže porodice i /ili po osnovu eventualne invalidnosti tih članova ili samog poreznog obveznika. Rezidentni porezni obveznici mogu odbiti i lični odbitak: 0,3 osnovnog ličnog odbitka iz stava (1) člana 24 za utvrđenu vlastitu invalidnost, kao i za utvrđenu invalidnost svakog člana uže porodice koje porezni obveznik izdržava. | D24: Novorođenče | E24: Poreske olakšice | F24: Poreska uprava Općine | K24: Zakn o porezu na dohodak FBiH | M24: Kopija lične karte Vjenčani list; Rodni list; Dokaz o visini prihoda izdržavanog lica; Uvjerenje o zajedničkom domaćinstvu; Rješenje nadležnog organa sa utvrđenim tjelesnim oštećenjem i stepena invaliditeta | P24: Diskrecione usluge
A25: 42 | B25: Posebna ishrana | D25: Novorođenče | E25: Zdravstvena zaštita | F25: Zavod zdravstvenog osiguranja KS | P25: Diskrecione usluge
A26: 52 | B26: Pravo na kućnu njegu | C26: Osoba može dobiti pomoć i njegu u kući ako ispunjava sljedeće uvjete: - Nije već dobila novčanu naknadu za pomoć i njegu od drugog. - Nema mogućnost da pomoć i njegu osiguraju roditelji, bračni partner ili djeca. - Nema mogućnost osiguranja pomoći i njege putem ugovora o doživotnom izdržavanju. - Prihod njezina kućanstva ne prelazi 30% prosječne plaće. | D26: Novorođenče | E26: Socijalna zaštita | H26: Moze li neko provjeriti u: Usluga dnevnog ili poludnevnog boravka u Centar za dnevni boravak – Gerontološki centar , u prvom sheetu | K26: Član 60 Pomoć i njega u kući može se odobriti osobi kojoj je zbog tjelesnog ili mentalnog oštećenja ili trajnih promjena u zdravstvenom stanju ili starosti prijeko potrebna pomoć i njega druge osobe pod uvjetom: - da nije ostvarila pravo na novčanu naknadu za pomoć i njegu od strane druge osobe; - da nema mogućnosti da joj pomoć i njegu osiguraju roditelji, bračni drug i djeca; - da nema mogućnosti da pomoć i njegu osigura na temelju ugovora o doživotnom izdržavanju; - da prihod po članu domaćinstva ne prelazi 30% prosječne plaće. Potrebu za pomoć i njegu u kući utvrđuje Stručna institucija. | P26: Neinstitucionalizirana prava
A27: 58 | B27: Pravo roditelja njegovatelja na osiguranje | C27: Roditelji staratelji imaju isti status osiguranja kao i zaposleni pojedinci. | D27: Novorođenče | E27: Rad i zapošljavanje | K27: Član 11. (Naknada i doprinosi) (1) Roditelj njegovatelj ima pravo na mjesečnu naknadu u visini iznosa neto najniže plaće u Federaciji Bosne i Hercegovine u skladu sa Zakonom o radu ("Službene novine Federacije BiH", br. 26/16 i 89/18), na koju se uplaćuju doprinosi za penzijsko i invalidsko osiguranje, zdravstveno osiguranje i osiguranje za vrijeme nezaposlenosti. | P27: Neinstitucionalizirana prava
A28: 59 | B28: Pravo roditelja njegovatelja na pokrivanje troškova sahrane/dženaze | C28: Roditelji staratelji dobijaju troškove sahrane za preminulu osobu sa invaliditetom, slično kao i federalni službenici. Roditelju lica s invaliditetom može se priznati status roditelja njegovatelja ukoliko je nazaposlen i prijavljen na evidenciji nadležne službe za zapošljavanje. Status roditelja njegovatelja priznaje se jednom od roditelja lica s invaliditetom sa 100% oštećenjem organizma i pravom na dodatak za njegu i pomoć od drugog lica. | D28: Novorođenče | E28: Socijalna zaštita | K28: Član 11. (Naknada i doprinosi) (4) U slučaju smrti lica sa invaliditetom, roditelj njegovatelj ostvaruje pravo na naknadu troškova ukopa – sahrane umrlog lica na isti način kako je to, drugim zakonima, regulisano za zaposlenike federalnih organa. | P28: Neinstitucionalizirana prava
A29: 60 | B29: Prednost u primanju usluga u zdravstvenom i drugim institucijama | D29: Novorođenče | E29: Zdravstvena zaštita | P29: Neinstitucionalizirana prava
A30: 24 | B30: Smještaj u hospis | C30: Zbrinjavanje teško oboljelih u zdravstveno-socijalnoj ustanovi | D30: Novorođenče | E30: Zdravstvena zaštita | F30: Zavod zdravstveno osiguranja Kantona Sarajevo | G30: Ložionička 2, 71000 Sarajevo, Bosna i Hercegovina | H30: https://www.kzzosa.ba/ | I30: 38733725207 | J30: info@kzzosa.ba | K30: Ugovor sa zdravstveno-socijalnom ustanovom | L30: Porodični ljekari, prema kriterijumima utvrđenim od Ministarstva zdravstva KS, pacijenta u terminalnoj fazi bolesti upućuje u zdravstveno-socijalnu ustanovu na odgovarajuću skrb (medicinska i psihološka podrška) | P30: Administrativni postupci
A31: 22 | B31: Refundacija troškova lijekova i liječenja | C31: Pravo na refundiranje troškova lijekova, medicinskih sredstava i liječenja koji nisu obuhvaćeni obaveznim zdravstvenim osiguranjem (odobravanje sredstava do 20.000KM) | D31: Predškolska dob | E31: Zdravstvena zaštita | F31: Zavod zdravstvenog osiguranja Kantona Sarajevo | G31: Ložionička 2, 71000 Sarajevo, Bosna i Hercegovina | H31: https://www.kzzosa.ba/ | I31: 38733725207 | J31: info@kzzosa.ba | K31: Pravilnik o načinu ostvarivanja prava iz obaveznog zdravstvenog osiguranja ("Sl.novine FBiH" br 31/02 i 20/19) i odluke ZZOKS | L31: Zahtjev za refundaciju troškova lijeka, medicinskog sredstva ili liječenja koji nisu obuhvaćenim obaveznim zdravstvenim osiguranjem, a preporučeni su pacijentu, podnosi se ZZO KS (odlučuje posebna komisija). Uz zahtjev se dostavlja medicinska dokumentacija kojom je preporučeno lijek, liječenje ili medicinsko sredstvo, potvrda o prebivalištu i originalni račun o plaćenom lijeku, liječenju ili medicinskom sredstvu. | P31: Administrativni postupci
A32: 2 | B32: Dodatak za njegu i pomoć od strane drugog lica, Civilne žrtve rata | C32: Pravo na dodatak za pomoć i njegu od strane druge osobe invalidima od I do IV grupe koji su nesposobni za vršenje osnovnih životnih potreba bez pomoći drugog lica. | D32: Predškolska dob | E32: Zaštita civilnih žrtava rata | F32: Općina, nadležna općinska služba Ministarstvo za rad, socijalnu politiku, raseljena lica i izbjeglice Kantona Sarajevo | G32: Primjer Općine Centar | H32: https://eregistar.centar.ba/registar/12-21-pravo-na-dodatak-za-njegu-i-pomoc-od-strane-drugog-lica-czr/ | I32: 0038733562450 | J32: zlatan.kulovic@centar.ba | K32: Zakon o osnovama socijalne zaštite, zaštite civilnih žrtava rata i zaštite porodice sa djecom („Službene novine Federacije Bosne i Hercegovine“, br. 36/99, 54/04, 39/06, 14/09, 45/16 i 40/18); član 60. Instrukcija o iznosima novčanih davanja po Zakonu o socijalnoj zaštiti, zaštiti civilnih žrtava rata i zaštiti porodice sa djecom – Instrukciju svake kalendarske godine donosi ministar za rad, socijalnu politiku, raseljena lica i izbjeglice Kantona Sarajevo. | L32: državljanstvo Bosne i Hercegovine;Potreba za tuđom njegom i pomoći civilne žrtve rata utvrđuje se na osnovu nalaza i mišljenja nadležne ljekarske komisije određene propisom ministra Federalnog ministarstva rada i socijalne politike. Vodi se upravni postupak u kojem se utvrđuje ispunjavanje uslova za ostvarivanje prava na dodatak za njegu i pomoć od strane drugog lica. Podnosilac zahtjeva ima pravo podnijeti žalbu na rješenje prvostepenog organa kojim nije ostvario pravo na dodatak za njegu i pomoć od strane drugog lica Ministarstvu za rad, socijalnu politiku, raseljena lica i izbjeglice Kantona Sarajevo, kao i pokrenuti upravni spor pred Kantonalnim sudom u Sarajevu. da ima priznat status civilne žrtve rata i pravo na ličnu invalidninu i da je nalazom i mišljenjem od strane ljekarske komisije utvrđena potreba za ortopedskim dodatkom. • | M32: Zahtjev za ostvarivanje prava na dodatak za njegu i pomoć od strane drugog lica podnosi se općini, nadležnoj općinskoj službi općine u kojoj podnosilac zahtjeva ima prebivalište. • • rješenje o priznavanju statusa civilne žrtve rata i prava na ličnu invalidninu; • ovjerena kopija lične karte; • CIPS prijava o mjestu prebivališta i • medicinska dokumentacija. Uvjerenje o nekažnjavanju, Ovjerena izjava u skladu sa čl.7, stav 1. i 2., čl.74, čl.75, čl.76a i čl.77 Zakona o osnovama socijalne zaštite, zaštite civilnih žrtava rata i zaštite porodice sa djecom („Službene novine FBiH“ broj 36/99,54/04,39/06,14/09,45/16 i 40/18), Tekući račun podnosioca zahtjeva | P32: Administrativni postupci
A33: 13 | B33: Ocjenjivanje sposobnosti, razvrstavanje djece i omladine ometene u psiho-fizičkom razvoju | C33: Utvrđivanja preostale sposobnosti i razvrstavanja djece i omladine, vodi se do navršene 18. godine života djeteta. | D33: Predškolska dob | E33: Socijalna zaštita | F33: Kantonalni centar za socijalni rad | G33: Gatačka 80, Sarajevo | H33: https://kcsr.ba/ | I33: 38733723640 | J33: info@kcsr.ba | K33: Pravilnik o utvrđivanju preostale sposobnosti i razvrstavanju djece i omladine ometene u psiho-fizičkom razvoju KS | M33: https://kcsr.ba/file/kcsr21/274 | N33: https://kcsr.ba/file/kcsr21/274 | P33: Administrativni postupci
A34: 25 | B34: Smještaj u ustanovu, njega, rehabilitacija i socijalna zaštita – Dom za djecu bez roditeljskog staranja | C34: Cjelokupno zbrinjavanje, odgoj, školovanje, zdravstvena zaštita djece bez roditelja i djece čiji je razvoj ometen porodičnim prilikama. | D34: Predškolska dob | E34: Socijalna zaštita | F34: Kantonalna javna ustanova Dom za djecu bez roditeljskog staranja Javna ustanova “Kantonalni centar za socijalni rad” – službe socijalne zaštite Ministarstvo za rad, socijalnu politiku, raseljena lica i izbjeglice Kantona Sarajevo | G34: Bjelave 52, 71000 Sarajevo, Bosna i Hercegovina | H34: https://dombjelave.ba/bs | I34: 38733209044 | J34: dombjelave@hotmail.com | K34: Član 85 Dom za socijalno i zdravstveno zbrinjavanje osoba sa invaliditetom i drugih osoba obavlja poslove socijalno-zdravstvenog zbrinjavanja odraslih tjelesno i mentalno invalidnih osoba, osoba sa trajnim smetnjama u fizičkom ili psihičkom razvoju, duševno oboljelih i hronično bolesnih osoba, osoba sa specifičnim oboljenjima, ako ne postoje osnovni uvjeti za smještaj u vlastitoj ili drugoj porodici ili drugoj ustanovi, a nije im neophodno bolničko liječenje ili je bolničko liječenje završeno. • Zakon o socijalnoj zaštiti, zaštiti civilnih žrtava rata i zaštiti porodice sa djecom („Službene novine Kantona Sarajevo“ br. 38/14 – Prečišćeni tekst, 38/16, 44/17 i 28/18); član 94. | M34: zahtjev za smještaj; rješenje o smještaju; socijalna anamneza; izvod iz matične knjige rođenih; zdravstvena knjižica; medicinska dokumentacija (ukoliko dijete ima zdravstvene poteškoće) i rješenje o starateljstvu (ukoliko je dijete pod starateljstvom nadležne službe). | P34: Administrativni postupci
A35: 4 | B35: Jednokratna novčana pomoć licima i domaćinstvima sa područja općine Novo Sarajevo | C35: Jednokratna novčana pomoć licima i domaćinstvima sa područja općine Novo Sarajevo samo za osobe za prebivalištem u Općini Novo Sarajevo | D35: Predškolska dob | E35: Socijalna zaštita | F35: Općina Novo Sarajevo | G35: Zmaja od Bosne 55, 71000 Sarajevo, Bosna i Hercegovina | H35: https://novosarajevo.ba/ | I35: 38733492125 | J35: socijalna.pitanja@novosarajevo.ba | K35: Odluka o uslovima, načinu, kriterijima i iznosu sredstava za dodjelu jednokratne novčane pomoći licima i domaćinstvima sa područja općine Novo Sarajevo ("Službene novine Kantona Sarajevo", broj: 19/21 i 19/22) | L35: Zahtjev se predaje Službi za socijalna pitanja, zdravstvo, izbjeglice i raseljena lica na propisanom obrascu, na kojem je navedena dokumentacija koju je potrebno priložiti. | M35: izjava - saglasnost za obradu podataka potvrda prijave mjesta prebivališta-boravišta (CIPS) za sve članove domaćinstva potvrda mjesne zajednice ili ovjerena kućna lista o broju članova domaćinstva potvrda banke o otvorenom žiro-računu preporuke stručnog lica medicinske struke original računi i dokaz o participaciji od Zavoda zdravstvenog osiguranja KS pravosnažno Rješenje ili uvjerenje JU "Centar za socijalni rad" dokaz o primanjima za sve članove domaćinstva ili potvrda o redovnom školovanju uvjerenje iz JU "Centar za socijalni rad" da li je njihov korisnik po bilo kom osnovu, za sve članove domaćinstva uvjerenje Porezne uprave, za sve članove domaćinstva | N35: https://novosarajevo.ba/userfiles/doc/files/Odluka_o_uslovima.pdf | O35: Zahtjevi se podnose tokom čitave godine, ali se pravo ostvaruje jednom u toku kalendarske godine | P35: Administrativni postupci
A36: 7 | B36: Kupovina lijekova po posebnim protokolima | C36: Pravo na liječenje rijetkih i teških oboljenja po posebnim protokolima (reumatoidini artritis, juvenilni idiopatski artritis, enteralna prehrana, bezglutensko brašno za oboljele od celijaklije) | D36: Predškolska dob | E36: Zdravstvena zaštita | F36: Zavod zdravstvenog osiguranja Kantona Sarajevo/zdravstvene ustanove | G36: Ložionička 2, 71000 Sarajevo, Bosna i Hercegovina | H36: https://www.kzzosa.ba/ | I36: 38733725207 | J36: info@kzzosa.ba | K36: Posebni protokoli (zaključuju se na godišnjem nivou, dostupni na stranici Zavoda, rubrika Javnost rada) | L36: Ovlašteni ljekari (posebno utvrđeni po svakom protokolu) predlažu, a u odnosu na raspoloživa sredstva, komisija odobrava. Zdravstvena ustanova u kojoj su propisivači direktno podnosi zahtjev za uključivanjem pacijenta, a nakon odobrenja, na osnovu propisanog recepta pacijent ostvaruje pravo na lijek/sredstvo u apotekama ili neposredno u zdravstvenim ustanovama (ukoliko se po prirodi protokola liječenja, lijek aplicira samo u bolničkim uslovima) | P36: Administrativni postupci
A37: 8 | B37: Medicinska rehabilitacija/banjsko liječenje kao produženo bolničko liječenje | C37: Pravo na medicinsku rehabilitaciju u ugovornim banjama | D37: Predškolska dob | E37: Zdravstvena zaštita | F37: Zavod zdravstvenog osiguranja Kantona Sarajevo | G37: Ložionička 2, 71000 Sarajevo, Bosna i Hercegovina | H37: https://www.kzzosa.ba/ | I37: 38733725207 | J37: info@kzzosa.ba | K37: Odluka o utvrđivanju osnovnog paketa zdravstvenih prava ("Sl.novine FBiH" br. 21/09) | L37: Ovlašteni ljekar/propisivač (neurolog, kardiolog itd) izdaju preporuku za medicinsku rehabilitaciju, koja se ovjerava u ZZO KS i osiguranik upućuje na medicinsku rehabilitaciju do 21 dana | P37: Administrativni postupci
A38: 9 | B38: Medicinska sredstva - ortopedska pomagala | C38: Pravo na medicinska sredstva/ortopedska pomagala za osiguranike u Kantonu Sarajevo | D38: Predškolska dob | E38: Zdravstvena zaštita | F38: Zavod zdravstvenog osiguranja Kantona Sarajevo | G38: Ložionička 2, 71000 Sarajevo, Bosna i Hercegovina | H38: https://www.kzzosa.ba/ | I38: 38733725207 | J38: info@kzzosa.ba | K38: Odluka o obimu, uslovima i načinu ostvarivanja prava osiguranih lica Kantona Sarajevo na medicinska sredstva ("Službene novine Kantona Sarajevo", broj: 22/20, 30/21, 42/22 i 48/22) | L38: Ovlašteni ljekar/propisivač )ljekar porodične medicine, neurolog, dijabetolog itd.) popunjavaju obrazac o pravu na medicinsko sredstvo koji se ovjerava u ZZO KS i nakon toga osiguranik preuzima propisano medicinsko sredstvo u apotekama i/ili specijaliziranim trgovinama za promet medicinskim sredstvima | P38: Administrativni postupci
A39: 15 | B39: Pravo na ličnu invalidninu, dodatak za njegu i pomoć drugog lica i ortopedski dodatak | C39: Licima sa invaliditetom i grupe sa 100% tjelesnog oštećenja i licima sa invaliditetom II grupe sa 90% tjelesnog oštećenja, omogućiti ostvarivanje prava na ličnu invalidninu, dodatak za njegu i pomoć od strane drugog lica i ortopedski dodatak. | D39: Predškolska dob | E39: Socijalna zaštita | F39: Kantonalni centar za socijalni rad | G39: Gatačka 80, Sarajevo | H39: https://kcsr.ba/ | I39: 38733723635 | J39: mirsada@kcsr.ba | K39: Zakon o osnovama socijalne zaštite zaštite civilnih žrtava rata i zaštite porodice sa djecom Federacije BiH Zakon o socijalnoj zaštiti, zaštiti civilnih žrtava rata i zaštiti porodice sa djecom Kantona Sarajevo | L39: (uvjerenje se pribavlja u općini prebivališta /boravišta podnosioca zahtjeva) (uvjerenje se pribavlja u općini prebivališta podnosioca zahtjeva) | M39: https://kcsr.ba/file/kcsr13/268 | N39: https://kcsr.ba/file/kcsr13/268 | P39: Administrativni postupci
A40: 19 | B40: Pravo na stalnu novčanu pomoć | C40: Ostvarivanje prava na materijalnu pomoć licima nesposobnim za rad, bez sredstava za život i srodnika koji su po Zakonu obavezni na izdržavanje. | D40: Predškolska dob | E40: Socijalna zaštita | F40: Kantonalni centar za socijalni rad | G40: Gatačka 80, Sarajevo | H40: https://kcsr.ba/ | I40: 38733723635 | J40: mirsada@kcsr.ba | K40: Zakon o osnovama socijalne zaštite zaštite civilnih žrtava rata i zaštite porodice sa djecom Federacije BiH Zakon o socijalnoj zaštiti, zaštiti civilnih žrtava rata i zaštiti porodice sa djecom Kantona Sarajevo | L40: (matični ured prema mjestu rodjenja maloljetne osobe) (dokaz o primanjima – potvrda o visini ličnog dohotka, potvrda službe za zapošljavanje, potvrda PIO, potvrda škole/fakulteta) (nadležna je općina prebivališta članova domaćinstva) (dokaz o kvadraturi stambenog prostora -utvrdjuje se od strane stručnih radnika -na terenu – općine koja vodi postupak po osnovu zahtjeva) (nadležna je služba općine za obavljanje poslova iz oblasti zaštite civilnih žrtava rata i zaštite porodice sa djecom) (matični ured prema mjestu rodjenja maloljetne osobe) (nadležna je općina prebivališta članova domaćinstva) (Prema prebivalištu podnosioca zahtjeva) | M40: https://kcsr.ba/file/kcsr4/262 | N40: https://kcsr.ba/file/kcsr4/262 | P40: Administrativni postupci
...

Sheet Sheet1
A1: Adresa | B1: Lat | C1: Lon
A2: Kranjčevićeva 12, Sarajevo | B2: 43.858553 | C2: 18.4021
A3: Reisa Džemaludina Čauševića 1, 71000 Sarajevo | B3: 43.857349 | C3: 18.413136
A4: Butmirska cesta 12, prvi sprat | B4: 43.829456 | C4: 18.310952
A5: Bulevar Meše Selimovića 12 | B5: 43.847951 | C5: 18.353697
A6: Zmaja od Bosne 88 | B6: 43.852588 | C6: 18.381644
A7: Ložionička 2 | B7: 43.85633 | C7: 18.384492
A8: Reisa Džemaludina Čauševića 1, 71000 Sarajevo | B8: 43.857349 | C8: 18.413136
A9: Bolnička 4, Sarajevo | B9: 43.867171 | C9: 18.413271
A10: Aleja Bosne Srebrene 7 71000 Sarajevo | B10: 43.833868 | C10: 18.331839
A11: Primjer Općine Centar | B11: 43.899231 | C11: 18.415161
A12: La Benevolencija 16 | B12: 43.857481 | C12: 18.416157
A13: Zmaja od Bosne 55, 71000 Sarajevo, Bosna i Hercegovina | B13: 43.851797 | C13: 18.382772
... A20: Bjelave 52, 71000 Sarajevo, Bosna i Hercegovina | B20: 43.856849 | C20: 18.384989

Sheet HOME

Sheet Dijagnoza
B2: MEDICINSKO VJEŠTAČENJE
B6: Prvi korak u slučaju sumnje na određeni stupanj invaliditeta podrazumijeva postavljanje dijagnoze i medicinsko vještačenje. Dijagnoza se postavlja u suradnji s liječnicima i specijalistima, nakon čega je potrebno zakazati medicinsko vještačenje u odgovarajućem zdravstvenom institutu ili bolnici. Proces dijagnosticiranja može se sažeti kroz sljedeće korake:
M28: Zahtjev za medicinsko vještačenje možete preuzeti: | S28: OVDJE

Sheet Predskolska
B12: Administrativni postupci | C12: Medicinska rehabilitacija/banjsko liječenje kao produženo bolničko liječenje | E12: =VLOOKUP(C12,Table2[[Naziv ]:[Dodatne napomene]],2,0) -> Pravo na medicinsku rehabilitaciju u ugovornim banjama | F12: =VLOOKUP(C12,Table2[[Naziv ]:[Dodatne napomene]],6,0) -> Zavod zdravstvenog osiguranja Kantona Sarajevo | G12: =VLOOKUP(C12,Table2[[Naziv ]:[Dodatne napomene]],7,0) -> Ložionička 2, 71000 Sarajevo, Bosna i Hercegovina | H12: =VLOOKUP(C12,Table2[[Naziv ]:[Dodatne napomene]],9,0) -> 38733725207
B14: Diskrecione usluge | C14: Subvencija za djecu istih roditelja - oslobađanje plaćanja vrtića za braću i sestre djeteta sa poteškoćama u razvoju | E14: =VLOOKUP(C14,Table5[],2,0) -> Djeca koja su braća/sestre djeteta sa poteškoćama u razvoju imaju pravo na subvenciju troškova vrtića. | F14: =VLOOKUP(C14,Table5[],6,0) -> Nadležna općina | G14: =VLOOKUP(C14,Table5[],7,0) -> 0 | H14: =VLOOKUP(C14,Table5[],9,0) -> 0
